<?xml version="1.0" ?>

<robot name="terraflight" xmlns:xacro="http://wiki.ros.org/wiki/xacro">

<material name="grey">
    <color rgba="0.7529 0.7529 0.7529 1.0"/>
</material>

<material name="dark">
    <color rgba="0.2 0.2 0.2 1.0"/>
</material>

<link name="base_footprint"/>

<joint name="base_joint" type="fixed">
    <parent link="base_footprint"/>
    <child link="base_link"/>
    <origin xyz="0.254 0 0.1226125" rpy="0 0 3.141592653589"/>
    <!-- x 0.254 -->
</joint>

<link name="base_link"/>

<joint name="base_link_to_laser" type="fixed">
    <parent link="base_link"/>
    <child link="laser"/>
    <origin xyz="0.05 0 0.2" rpy="3.141592 0 3.141592"/>
</joint>

<link name="laser"/>

<joint name="base_link_to_chassis" type="fixed">
    <parent link="base_link"/>
    <child link="chassis"/>
    <origin xyz="0 0 0"/>
</joint>

<link name="chassis">
    <visual>
        <origin xyz="0 0 0" rpy="0 0 0"/>
        <geometry>
            <mesh filename="package://terraflight_description/meshes/chassis.stl" scale="1 1 1"/>
        </geometry>
        <material name="grey" />
    </visual>

</link>

<joint name="front_left_joint" type="continuous">
    <parent link="chassis"/>
    <child link="front_left_wheel"/>
    <origin xyz="0 -.3433115 -0.0427975"/>
    <axis xyz="0 1 0"/>
</joint>


<link name="front_left_wheel">
    <visual>
        <origin xyz="0 0 0" rpy="1.5708 0 0"/>
        <geometry>
            <mesh filename="package://terraflight_description/meshes/front_left_wheel.stl" scale="1 1 1"/>
        </geometry>
        <material name="dark"/>
    </visual>
</link>

<joint name="back_left_joint" type="continuous">
    <parent link="chassis"/>
    <child link="back_left_wheel"/>
    <origin xyz=".4826 -.3433115 -0.0427975"/>
    <axis xyz="0 1 0"/>
</joint>


<link name="back_left_wheel">
    <visual>
        <origin xyz="0 0 0" rpy="1.5708 0 0"/>
        <geometry>
            <mesh filename="package://terraflight_description/meshes/back_left_wheel.stl" scale="1 1 1"/>
        </geometry>
        <material name="dark"/>
    </visual>
</link>

<joint name="front_right_joint" type="continuous">
    <parent link="chassis"/>
    <child link="front_right_wheel"/>
    <origin xyz="0 .3433115 -0.0427975"/>
    <axis xyz="0 1 0"/>
</joint>


<link name="front_right_wheel">
    <visual>
        <origin xyz="0 0 0" rpy="-1.5708 0 0"/>
        <geometry>
            <mesh filename="package://terraflight_description/meshes/front_right_wheel.stl" scale="1 1 1"/>
        </geometry>
        <material name="dark"/>
    </visual>
</link>

<joint name="back_right_joint" type="continuous">
    <parent link="chassis"/>
    <child link="back_right_wheel"/>
    <origin xyz=".4826 .3433115 -0.0427975"/>
    <axis xyz="0 1 0"/>
</joint>


<link name="back_right_wheel">
    <visual>
        <origin xyz="0 0 0" rpy="1.5708 0 0"/>
        <geometry>
            <mesh filename="package://terraflight_description/meshes/back_right_wheel.stl" scale="1 1 1"/>
        </geometry>
        <material name="dark"/>
    </visual>
</link>


</robot>